<?xml version="1.0"?>
<robot	name="thedush_arm_full_robot">

	<material name="theme">
		<texture filename="package://thedush_arm_full_robot/textures/texture1.png"/>
	</material>

	<material name="theme1">
		<texture filename="package://thedush_arm_full_robot/textures/texture2.png"/>
	</material>
	<material name="Black">
    	<color rgba="0.0 0.0 0.0 1.0"/>
  	</material>
  	<material name="White">
   		<color rgba="1.0 1.0 1.0 1.0"/>
 	</material>



	<joint name="bottom_joint" type="fixed">
		<origin rpy="0 0 0" xyz="0 0 0"/>
		<parent link="base_link"/>
		<child link="bottom_link"/>
	</joint>

	<link name="bottom_link">
		<visual>
			<origin rpy="0 0 0" xyz=" 0 0 -0.04"/>
			<geometry>
				<box size="1 1 0.04"/>
			</geometry>
			<material name="White"/>
		</visual>
		<collision>
			<origin rpy="0 0 0" xyz=" 0 0 -0.04"/>
			<geometry>
				<box size="1 1 0.04"/>
			</geometry>
		</collision>
		&gt;
	</link>
	<gazebo reference="bottom_link">
		<turnGravityOff>false</turnGravityOff>
    	<material>Gazebo/Orange</material>
  	</gazebo>

	<link name="base_link">
		<inertial>
      		<mass value="1"/>
      		<inertia ixx="1.0" ixy="0.0" ixz="0.0" iyy="0.5" iyz="0.0" izz="1.0"/>
    	</inertial>
		<visual>
			<origin xyz="-0.05 0.2 -0.08" rpy="0 0 0" />
			<geometry>
				<mesh filename="package://thedush_arm_full_robot/meshes/base_link.STL" />
			</geometry>
			 <material name="theme1"/>
		</visual>
		<collision>
			<origin xyz="-0.05 0.2 -0.08" rpy="0 0 0" />
			<geometry>
				<mesh filename="package://thedush_arm_full_robot/meshes/base_link.STL" />
			</geometry>
		</collision>
	</link>
	<gazebo reference="base_link">
    	<material>Gazebo/Orange</material>
    	<turnGravityOff>false</turnGravityOff>
  	</gazebo>

	<joint name="arm_joint" type="continuous">
		<origin xyz="0.0930626575947 -0.0050 -0.0090733811855"	rpy="1.5708 -5.9837E-20 -0.00097724" />
		<parent link="base_link" />
		<child link="arm_link" />
		<axis xyz="0 1 0" />
		<limit	effort="0"	velocity="1" />
		<dynamics damping="50" friction="1"/>
	</joint>



	<link name="arm_link">
		<inertial>
      		<mass value="1"/>
      		<inertia ixx="1.0" ixy="0.0" ixz="0.0" iyy="0.5" iyz="0.0" izz="1.0"/>
    	</inertial>

		<visual>
			<origin	xyz="0.0000 0.0 0.00"   rpy="0 0 0" />
			<geometry>
				<mesh	filename="package://thedush_arm_full_robot/meshes/arm_link.STL" />
			</geometry>
			 <material name="Black"/>
		</visual>
		<collision>
			<origin xyz="0 0 0" rpy="0 0 0" />
			<geometry>
				<mesh filename="package://thedush_arm_full_robot/meshes/arm_link.STL" />
			</geometry>
		</collision>
	</link>
	<gazebo reference="arm_link">
    	<material>Gazebo/Orange</material>
    	<turnGravityOff>false</turnGravityOff>
  	</gazebo>


	<joint	name="shoulder_joint"    type="continuous">
		<origin xyz="0.064038629103 0.164269309998 -0.0224439656734" rpy="0 0 0" />
		<parent link="arm_link" />
		<child  link="shoulder_link" />
		<axis   xyz="0 0 -1" />
		<limit  effort="0" velocity="1" />
		<dynamics damping="50" friction="1"/>
	</joint>




	<link	name="shoulder_link">
		<inertial>
      		<mass value="1"/>
      		<inertia ixx="1.0" ixy="0.0" ixz="0.0" iyy="0.5" iyz="0.0" izz="1.0"/>
    	</inertial>
		<visual>
			<origin	xyz="-0.073 -0.30 -0.18"	rpy="-1.57 0 0.5" />
			<geometry>
				<mesh filename="package://thedush_arm_full_robot/meshes/shoulder_link.STL" />
			</geometry>
			 <material name="theme1"/>
		</visual>
		<collision>
			<origin	xyz="-0.073 -0.30 -0.18"	rpy="-1.57 0 0.5" />
			<geometry>
				<mesh filename="package://thedush_arm_full_robot/meshes/shoulder_link.STL" />
			</geometry>
		</collision>
	</link>

	<gazebo reference="shoulder_link">
    	<material>Gazebo/Orange</material>
    	<turnGravityOff>false</turnGravityOff>
  	</gazebo>


	<joint name="wrist_joint" 	type="continuous">
		<origin	xyz="-0.3540057327127 0.280243031311 -0.020028915405" 	rpy="4.1874E-06 3.5863E-15 -0.00411" />
		<parent	link="shoulder_link" />
		<child 	link="wrist_link" />
		<axis	xyz="0 0 1" />
		<limit	effort="0"	velocity="1" />
		<dynamics damping="50" friction="1"/>
	</joint>



	<link name="wrist_link">
		<inertial>
      		<mass value="1"/>
      		<inertia ixx="1.0" ixy="0.0" ixz="0.0" iyy="0.5" iyz="0.0" izz="1.0"/>
    	</inertial>
		<visual>
			<origin	xyz="-0.0325 -0.6445 -0.158"	rpy="4.71 0 0" />
			<geometry>
				<mesh	filename="package://thedush_arm_full_robot/meshes/wrist_link.STL" />
			</geometry>
			 <material name="theme"/>
		</visual>
		<collision>
			<origin	xyz="-0.0325 -0.6445 -0.158"	rpy="4.71 0 0" />
			<geometry>
				<mesh	filename="package://thedush_arm_full_robot/meshes/wrist_link.STL" />
			</geometry>
		</collision>
	</link>

	<gazebo reference="wrist_link">
    	<material>Gazebo/Orange</material>
    	<turnGravityOff>false</turnGravityOff>
  	</gazebo>





	<joint name="wrotate_joint"	type="continuous">
		<origin	xyz="-0.001856706738 0.00107652950287 0.05206165123"	rpy="0 0.01 0" />
		<parent	link="wrist_link" />
		<child	link="wrotate_link" />
		<axis	xyz="1 0 0" />
		<limit	effort="0"	velocity="1" />
		<dynamics damping="50" friction="1"/>
	</joint>






    <link  name="wrotate_link">
		<inertial>
      		<mass value="1"/>
      		<inertia ixx="1.0" ixy="0.0" ixz="0.0" iyy="0.5" iyz="0.0" izz="1.0"/>
    	</inertial>

		<visual>
			<origin	xyz="0.255 -0.013 0.05501"	rpy="0 -0.180 0" />
			<geometry>
				<mesh  filename="package://thedush_arm_full_robot/meshes/wrotate_link.STL" />
			</geometry>
			 <material name="theme"/>
		</visual>


		<collision>
			<origin	xyz="0.255 -0.013 0.05501"	rpy="0 -0.180 0" />
			<geometry>
				<mesh	filename="package://thedush_arm_full_robot/meshes/wrotate_link.STL" />
			</geometry>
		</collision>
	</link>

	<gazebo reference="wrotate_link">
    	<material>Gazebo/Orange</material>
    	<turnGravityOff>false</turnGravityOff>
  	</gazebo>


	<joint	name="tool_joint" type="continuous">
		<origin	xyz="0.482182 0.0480664 0.05352198" rpy="-2.9271 -0.26532 1.4974" />
		<parent	link="wrotate_link" />
		<child	link="tool_link" />
		<axis	xyz="0.31691 -0.22746 -0.92078" />
		<limit	effort="0"	velocity="1" />
		<dynamics damping="50" friction="1"/>
	</joint>



	<link  name="tool_link">
		<inertial>
      		<mass value="1"/>
      		<inertia ixx="1.0" ixy="0.0" ixz="0.0" iyy="0.5" iyz="0.0" izz="1.0"/>
    	</inertial>
		<visual>
			<origin	xyz="0 0 0"	rpy="0 0 0" />
			<geometry>
				<mesh	filename="package://thedush_arm_full_robot/meshes/tool_link.STL" />
			</geometry>
			 <material name="theme"/>
		</visual>
		<collision>
			<origin	xyz="0 0 0"	rpy="0 0 0" />
			<geometry>
					<mesh	filename="package://thedush_arm_full_robot/meshes/tool_link.STL" />
			</geometry>
		</collision>
	</link>

	<gazebo reference="tool_link">
    	<material>Gazebo/Orange</material>
    	<turnGravityOff>false</turnGravityOff>
  	</gazebo>


<transmission name="tran2">
    <type>transmission_interface/SimpleTransmission</type>
    <joint name="arm_joint">
      <hardwareInterface>PositionJointInterface</hardwareInterface>
    </joint>
    <actuator name="motor2">
      <hardwareInterface>PositionJointInterface</hardwareInterface>
      <mechanicalReduction>1</mechanicalReduction>
    </actuator>
  </transmission>
  <transmission name="tran2">
    <type>transmission_interface/SimpleTransmission</type>
    <joint name="shoulder_joint">
      <hardwareInterface>PositionJointInterface</hardwareInterface>
    </joint>
    <actuator name="motor2">
      <hardwareInterface>PositionJointInterface</hardwareInterface>
      <mechanicalReduction>1</mechanicalReduction>
    </actuator>
  </transmission>
  <transmission name="tran2">
    <type>transmission_interface/SimpleTransmission</type>
    <joint name="wrist_joint">
      <hardwareInterface>PositionJointInterface</hardwareInterface>
    </joint>
    <actuator name="motor2">
      <hardwareInterface>PositionJointInterface</hardwareInterface>
      <mechanicalReduction>1</mechanicalReduction>
    </actuator>
  </transmission>
  <transmission name="tran2">
    <type>transmission_interface/SimpleTransmission</type>
    <joint name="wrotate_joint">
      <hardwareInterface>PositionJointInterface</hardwareInterface>
    </joint>
    <actuator name="motor2">
      <hardwareInterface>PositionJointInterface</hardwareInterface>
      <mechanicalReduction>1</mechanicalReduction>
    </actuator>
  </transmission>
  <transmission name="tran2">
    <type>transmission_interface/SimpleTransmission</type>
    <joint name="tool_joint">
      <hardwareInterface>PositionJointInterface</hardwareInterface>
    </joint>
    <actuator name="motor2">
      <hardwareInterface>PositionJointInterface</hardwareInterface>
      <mechanicalReduction>1</mechanicalReduction>
    </actuator>
  </transmission>
    <gazebo>
    <plugin filename="libgazebo_ros_control.so" name="gazebo_ros_control">
      <robotNamespace>/thedush_arm_full_robot</robotNamespace>
    </plugin>
  </gazebo>
</robot>
